Workbook

Sheet MASTER SHEET
A1: SOUKYA VILLAS - PRICE MASTER | X1: =TODAY() -> 46237
A2: Sl. No. | B2: Villa No. | C2: Premium & Ultra Premium | D2: Reason for Premium | E2: Apt. Status | F2: Wing | G2: VILLA TYPE | H2: Land Area (Sq.mt) | I2: Land Area (Sq.ft) | J2: Additional Land Area (Sq.ft) | K2: Rate Per Sft for Additional Land Area | L2: Salable Area (Sq.mt) | M2: Salable Area (Sq.ft) | N2: Carpet Area (sq.mts) | O2: BASE RATE /SFT | P2: Premium Charges | Q2: Sale Value (Basic Cost+Car Park) | R2: GST on Sale Value | S2: Basic Salevalue with GST | T2: E-stamping Charges | U2: Maintenance Charges | V2: Refundable Corpus Funds | W2: Gross Apartment Value (Rs.) | X2: All Inclusive Per Sft Unit Price
A3: 1 | B3: A1 | C3: Premium | D3: Corner Villa | E3: AVLBL | F3: A | G3: LUNA | H3: 186.49 | I3: =H3*10.76391041671 -> 2007.3617 | J3: =I3-2007.362 -> -0.00034638775 | L3: 324.23 | M3: 3490 | N3: 232.14 | O3: 11300 | P3: 1000000 | Q3: =(M3*O3)+P3 -> 40437000 | R3: =Q3*5% -> 2021850 | S3: =(Q3+R3) -> 42458850 | T3: =Q3*0.5% -> 202185 | U3: =(7*24*M3)+(7*24*M3)*18% -> 691857.6 | V3: =(84*M3) -> 293160 | W3: =SUM(S3+T3+U3+V3) -> 43646053 | X3: =W3/M3 -> 12506.032
A4: 2 | B4: A2 | E4: AVLBL | F4: A | G4: LUNA | H4: 186.49 | I4: =H4*10.76391041671 -> 2007.3617 | J4: =I4-2007.362 -> -0.00034638775 | L4: 324.23 | M4: 3490 | N4: 232.14 | O4: 12292 | P4: 0 | Q4: =(M4*O4)+P4 -> 42899080 | R4: =Q4*5% -> 2144954 | S4: =(Q4+R4) -> 45044034 | T4: =Q4*0.5% -> 214495.4 | U4: =(7*24*M4)+(7*24*M4)*18% -> 691857.6 | V4: =(84*M4) -> 293160 | W4: =SUM(S4+T4+U4+V4) -> 46243547 | X4: =W4/M4 -> 13250.3
A5: 3 | B5: A3 | E5: AVLBL | F5: A | G5: LUNA | H5: 186.49 | I5: =H5*10.76391041671 -> 2007.3617 | J5: =I5-2007.362 -> -0.00034638775 | L5: 324.23 | M5: 3490 | N5: 232.14 | O5: 12281 | P5: 0 | Q5: =(M5*O5)+P5 -> 42860690 | R5: =Q5*5% -> 2143034.5 | S5: =(Q5+R5) -> 45003724 | T5: =Q5*0.5% -> 214303.45 | U5: =(7*24*M5)+(7*24*M5)*18% -> 691857.6 | V5: =(84*M5) -> 293160 | W5: =SUM(S5+T5+U5+V5) -> 46203046 | X5: =W5/M5 -> 13238.695
A6: 4 | B6: A4 | E6: AVLBL | F6: A | G6: LUNA | H6: 186.49 | I6: =H6*10.76391041671 -> 2007.3617 | J6: =I6-2007.362 -> -0.00034638775 | L6: 324.23 | M6: 3490 | N6: 232.14 | O6: 14000 | P6: 0 | Q6: =(M6*O6)+P6 -> 48860000 | R6: =Q6*5% -> 2443000 | S6: =(Q6+R6) -> 51303000 | T6: =Q6*0.5% -> 244300 | U6: =(7*24*M6)+(7*24*M6)*18% -> 691857.6 | V6: =(84*M6) -> 293160 | W6: =SUM(S6+T6+U6+V6) -> 52532318 | X6: =W6/M6 -> 15052.24
A7: 5 | B7: A5 | E7: AVLBL | F7: A | G7: LUNA | H7: 186.49 | I7: =H7*10.76391041671 -> 2007.3617 | J7: =I7-2007.362 -> -0.00034638775 | L7: 324.23 | M7: 3490 | N7: 232.14 | O7: 12050 | P7: 0 | Q7: =(M7*O7)+P7 -> 42054500 | R7: =Q7*5% -> 2102725 | S7: =(Q7+R7) -> 44157225 | T7: =Q7*0.5% -> 210272.5 | U7: =(7*24*M7)+(7*24*M7)*18% -> 691857.6 | V7: =(84*M7) -> 293160 | W7: =SUM(S7+T7+U7+V7) -> 45352515 | X7: =W7/M7 -> 12994.99

Sheet PRICE SHEET
B1: RIVIERA UNO - PRICE SHEET & PAYMENT SCHEDULE
B2: Allotted to: Mr. & Mrs.
B3: Row Villa No. | D3: A1
B4: Row Villa Type | D4: 4BHK ROW VILLA
B5: Demarcated Land Area (Sq.mt.) | D5: =IF(D4="4BHK ROW VILLA",VLOOKUP(D3,'MASTER SHEET'!B3:W7,7,FALSE)) -> 186.49
B6: Demarcated Land Area (Sq.ft.) | D6: =IF(D4="4BHK ROW VILLA",VLOOKUP(D3,'MASTER SHEET'!B3:W7,8,FALSE)) -> 2007.3617
B7: Saleable Area/ Super Builtup Area (Sq.mt.) | D7: =IF(D4="4BHK ROW VILLA",VLOOKUP(D3,'MASTER SHEET'!B3:W7,11,FALSE)) -> 324.23
B8: Saleable Area/ Super Builtup Area (Sq.ft.) | D8: =IF(D4="4BHK ROW VILLA",VLOOKUP(D3,'MASTER SHEET'!B3:W7,12,FALSE)) -> 3490
B9: Carpet Area in Sq.mt (RERA) | D9: =IF(D4="4BHK ROW VILLA",VLOOKUP(D3,'MASTER SHEET'!B3:W7,13,FALSE)) -> 232.14
B10: Unit Price per sq.ft. on Saleable Area (Rs.) | D10: =IF(D4="4BHK ROW VILLA",VLOOKUP(D3,'MASTER SHEET'!B3:W7,14,FALSE)) -> 11300
B11: Premium Charges (If applicable) | D11: =IF(D4="4BHK ROW VILLA",VLOOKUP(D3,'MASTER SHEET'!B3:W7,15,FALSE)) -> 1000000
B12: Basic Sale Value | D12: =IF(D4="4BHK ROW VILLA",VLOOKUP(D3,'MASTER SHEET'!B3:W7,16,FALSE)) -> 40437000
B13: GST applicable on Basic Sale Value (5%) | D13: =IF(D4="4BHK ROW VILLA",VLOOKUP(D3,'MASTER SHEET'!B3:W7,17,FALSE)) -> 2021850
B14: BASIC SALE VALUE WITH GST (A) | D14: =SUM(D12:D13) -> 42458850
B15: PAYMENT SCHEDULE
B16: Refundable Earnest Amount Deposits (READ) | C16: 0.1 | D16: 1000000
B17: Balance Booking Amount after adjusting (READ) payable upon agreement execution within 7 days from the accpetance of the application. | D17: =(C16*D14)-D16 -> 3245885
B18: On completion of Excavation | C18: 0.15 | D18: =C18*D14 -> 6368827.5
B19: On completion of Foundation | C19: 0.1 | D19: =C19*D14 -> 4245885
B20: On completion of Ground Floor Slab | C20: 0.1 | D20: =C20*D14 -> 4245885
B21: On completion of 1st Floor Slab | C21: 0.1 | D21: =C21*D14 -> 4245885
B22: On completion of Block work | C22: 0.1 | D22: =C22*D14 -> 4245885
B23: On completion of Plastering | C23: 0.1 | D23: =C23*D14 -> 4245885
B24: On completion of Flooring | C24: 0.1 | D24: =C24*D14 -> 4245885
B25: On completion of Painting | C25: 0.1 | D25: =C25*D14 -> 4245885
B26: On Possession/Registration whichever is earlier | C26: 0.05 | D26: =C26*D14 -> 2122942.5
B27: TOTAL | C27: =SUM(C16:C26) -> 1 | D27: =SUM(D16:D26) -> 42458850
B28: OTHER CHARGES & EXPENSES (B)
B29: E-stamping Charges | D29: =IF(D4="4BHK ROW VILLA",VLOOKUP(D3,'MASTER SHEET'!B3:W7,19,FALSE)) -> 202185
B30: Maintenance Charges for 24 months @ Rs.7/- per sft per month | D30: =IF(D4="4BHK ROW VILLA",VLOOKUP(D3,'MASTER SHEET'!B3:W7,20,FALSE)) -> 691857.6
B31: Refundable Corpus Fund | D31: =IF(D4="4BHK ROW VILLA",VLOOKUP(D3,'MASTER SHEET'!B3:W7,21,FALSE)) -> 293160
B32: SUB TOTAL (B) | D32: =SUM(D29:D31) -> 1187202.6
B33: GROSS VALUE (A) + (B) | D33: =D14+D32 -> 43646053
B34: Note::
B35: 1. Stamp Duty, Registration Charges and any other statutory payments to the governing authorities are additional and payable at the time of Registration or posession whicever is earlier.
B36: 2. GST as applicable to be borne by the allottee/s and payable along with every payments,should there be any changes by the governing authorities the same to be borne by the allottee/s.
B37: 3. Currently (GST @5% applicable on basic salevalue and on other charges and exepenses excluding Estamping & Refundable corpus fund**) (18% GST applicable on maintenace charges).
B38: 4. Balance 10% of the booking amount is payable within 7 days from the date of acceptance of the applications & to be given as a post dated cheque at the time of booking.
B39: 5. All payments to be made favouring "NIRVANA DEVELOPERS RERA COLLECTION ACCOUNT FOR RIVIERA UNO" payable at Bangalore only.
B40: 6. Delayed payment interest charged would attract additional applicable GST & incase of cancelation prior to agreement exectuion, refund amount will be after deducting GST.
...
